Traceback (most recent call last):
  File "/mnt/home/aaggarwal/miniconda3/envs/target-genes/lib/python3.10/site-packages/pandas/core/indexes/base.py", line 3812, in get_loc
    return self._engine.get_loc(casted_key)
  File "pandas/_libs/index.pyx", line 167, in pandas._libs.index.IndexEngine.get_loc
  File "pandas/_libs/index.pyx", line 196, in pandas._libs.index.IndexEngine.get_loc
  File "pandas/_libs/hashtable_class_helper.pxi", line 7088, in pandas._libs.hashtable.PyObjectHashTable.get_item
  File "pandas/_libs/hashtable_class_helper.pxi", line 7096, in pandas._libs.hashtable.PyObjectHashTable.get_item
KeyError: 'Chrom'

The above exception was the direct cause of the following exception:

Traceback (most recent call last):
  File "/mnt/home/aaggarwal/gates_proj/protein_translation/3_extract_var_sequences.py", line 300, in <module>
    main(
  File "/mnt/home/aaggarwal/gates_proj/protein_translation/3_extract_var_sequences.py", line 254, in main
    annotated_vcf = annotate_vcf_with_entrez(vcf, gtf_transcripts)
  File "/mnt/home/aaggarwal/gates_proj/protein_translation/3_extract_var_sequences.py", line 179, in annotate_vcf_with_entrez
    (vcf_df['Chrom'] == chrom) &
  File "/mnt/home/aaggarwal/miniconda3/envs/target-genes/lib/python3.10/site-packages/pandas/core/frame.py", line 4107, in __getitem__
    indexer = self.columns.get_loc(key)
  File "/mnt/home/aaggarwal/miniconda3/envs/target-genes/lib/python3.10/site-packages/pandas/core/indexes/base.py", line 3819, in get_loc
    raise KeyError(key) from err
KeyError: 'Chrom'
